<?xml version="1.0" ?>
<robot name="throwing_bot" xmlns:xacro="http://www.ros.org/wiki/xacro">

<xacro:include filename="$(find throwing_bot_description)/urdf/materials.xacro" />
<xacro:include filename="$(find throwing_bot_description)/urdf/throwing_bot.trans" />
<xacro:include filename="$(find throwing_bot_description)/gazebo/throwing_bot_materials.gazebo" />
<xacro:include filename="$(find throwing_bot_description)/gazebo/throwing_bot_physics.gazebo" />
<xacro:include filename="$(find throwing_bot_description)/gazebo/throwing_bot_plugins.gazebo" />
<link name="dummy">
</link>

<link name="base_link">
  <inertial>
    <origin rpy="0 0 0" xyz="-0.011726915164729915 -0.011147209992249073 0.2397796079481494"/>
    <mass value="317.96687849022385"/>
    <inertia ixx="35.143458" ixy="0.812101" ixz="0.024376" iyy="35.144731" iyz="0.019118" izz="57.642285"/>
  </inertial>
  <visual>
    <origin rpy="0 0 0" xyz="0 0 0"/>
    <geometry>
      <mesh filename="package://throwing_bot_description/meshes/base_link.stl" scale="0.001 0.001 0.001"/>
    </geometry>
    <material name="silver_default"/>
  </visual>
  <collision>
    <origin rpy="0 0 0" xyz="0 0 0"/>
    <geometry>
      <mesh filename="package://throwing_bot_description/meshes/base_link.stl" scale="0.001 0.001 0.001"/>
    </geometry>
  </collision>
</link>

<link name="rotating_chamber_roller_fr_2_1">
  <inertial>
    <origin rpy="0 0 0" xyz="9.51022514628086e-08 1.3912592186637873e-07 -0.00014705021665489815"/>
    <mass value="0.16224172662152384"/>
    <inertia ixx="4.6e-03" ixy="1.5e-03" ixz="0.0" iyy="4.6e-03" iyz="-0.0" izz="3.2e-03"/>
  </inertial>
  <visual>
    <origin rpy="0 0 0" xyz="-0.278375 0.062874 -0.273183"/>
    <geometry>
      <mesh filename="package://throwing_bot_description/meshes/rotating_chamber_roller_fr_2_1.stl" scale="0.001 0.001 0.001"/>
    </geometry>
    <material name="silver_default"/>
  </visual>
  <collision>
    <origin rpy="0 0 0" xyz="-0.278375 0.062874 -0.273183"/>
    <geometry>
      <mesh filename="package://throwing_bot_description/meshes/rotating_chamber_roller_fr_2_1.stl" scale="0.001 0.001 0.001"/>
    </geometry>
  </collision>
</link>

<link name="rotating_chamber_roller_fr_1_1">
  <inertial>
    <origin rpy="0 0 0" xyz="-2.1050117539334057e-07 -1.6647750339382483e-07 -0.0001470502166586729"/>
    <mass value="0.16224172662152384"/>
    <inertia ixx="4.6e-03" ixy="1.5e-03" ixz="0.0" iyy="4.6e-03" iyz="-0.0" izz="3.2e-03"/>
  </inertial>
  <visual>
    <origin rpy="0 0 0" xyz="-0.037959 0.30329 -0.273183"/>
    <geometry>
      <mesh filename="package://throwing_bot_description/meshes/rotating_chamber_roller_fr_1_1.stl" scale="0.001 0.001 0.001"/>
    </geometry>
    <material name="silver_default"/>
  </visual>
  <collision>
    <origin rpy="0 0 0" xyz="-0.037959 0.30329 -0.273183"/>
    <geometry>
      <mesh filename="package://throwing_bot_description/meshes/rotating_chamber_roller_fr_1_1.stl" scale="0.001 0.001 0.001"/>
    </geometry>
  </collision>
</link>

<link name="rotating_chamber_roller_bl_1_1">
  <inertial>
    <origin rpy="0 0 0" xyz="2.1607366723630506e-07 4.069476635532032e-07 0.00014646283254493575"/>
    <mass value="0.16224172662152384"/>
    <inertia ixx="4.6e-03" ixy="1.5e-03" ixz="-0.0" iyy="4.6e-03" iyz="0.0" izz="3.2e-03"/>
  </inertial>
  <visual>
    <origin rpy="0 0 0" xyz="0.306074 -0.040742 -0.273183"/>
    <geometry>
      <mesh filename="package://throwing_bot_description/meshes/rotating_chamber_roller_bl_1_1.stl" scale="0.001 0.001 0.001"/>
    </geometry>
    <material name="silver_default"/>
  </visual>
  <collision>
    <origin rpy="0 0 0" xyz="0.306074 -0.040742 -0.273183"/>
    <geometry>
      <mesh filename="package://throwing_bot_description/meshes/rotating_chamber_roller_bl_1_1.stl" scale="0.001 0.001 0.001"/>
    </geometry>
  </collision>
</link>

<link name="rotating_chamber_roller_bl_2_1">
  <inertial>
    <origin rpy="0 0 0" xyz="-4.783229011345869e-07 -2.8744891639176373e-07 0.0001464628325491546"/>
    <mass value="0.16224172662152384"/>
    <inertia ixx="4.6e-03" ixy="1.5e-03" ixz="-0.0" iyy="4.6e-03" iyz="0.0" izz="3.2e-03"/>
  </inertial>
  <visual>
    <origin rpy="0 0 0" xyz="0.065657 -0.281159 -0.273183"/>
    <geometry>
      <mesh filename="package://throwing_bot_description/meshes/rotating_chamber_roller_bl_2_1.stl" scale="0.001 0.001 0.001"/>
    </geometry>
    <material name="silver_default"/>
  </visual>
  <collision>
    <origin rpy="0 0 0" xyz="0.065657 -0.281159 -0.273183"/>
    <geometry>
      <mesh filename="package://throwing_bot_description/meshes/rotating_chamber_roller_bl_2_1.stl" scale="0.001 0.001 0.001"/>
    </geometry>
  </collision>
</link>

<link name="gripper_arm_fr_1">
  <inertial>
    <origin rpy="0 0 0" xyz="-1.3977562079992012e-07 4.770616845450881e-07 0.16198592525786618"/>
    <mass value="19.9230589366508"/>
    <inertia ixx="0.221537" ixy="-0.00275" ixz="0.0" iyy="0.221537" iyz="0.0" izz="0.027851"/>
  </inertial>
  <visual>
    <origin rpy="0 0 0" xyz="-0.333156 0.358242 -0.242924"/>
    <geometry>
      <mesh filename="package://throwing_bot_description/meshes/gripper_arm_fr_1.stl" scale="0.001 0.001 0.001"/>
    </geometry>
    <material name="silver_default"/>
  </visual>
  <collision>
    <origin rpy="0 0 0" xyz="-0.333156 0.358242 -0.242924"/>
    <geometry>
      <mesh filename="package://throwing_bot_description/meshes/gripper_arm_fr_1.stl" scale="0.001 0.001 0.001"/>
    </geometry>
  </collision>
</link>

<link name="gripper_arm_bl_1">
  <inertial>
    <origin rpy="0 0 0" xyz="4.959851588326458e-07 -1.5869908820409506e-07 0.16198592525786656"/>
    <mass value="19.9230589366508"/>
    <inertia ixx="0.221537" ixy="-0.00275" ixz="0.0" iyy="0.221537" iyz="-0.0" izz="0.027851"/>
  </inertial>
  <visual>
    <origin rpy="0 0 0" xyz="0.358242 -0.333156 -0.242924"/>
    <geometry>
      <mesh filename="package://throwing_bot_description/meshes/gripper_arm_bl_1.stl" scale="0.001 0.001 0.001"/>
    </geometry>
    <material name="silver_default"/>
  </visual>
  <collision>
    <origin rpy="0 0 0" xyz="0.358242 -0.333156 -0.242924"/>
    <geometry>
      <mesh filename="package://throwing_bot_description/meshes/gripper_arm_bl_1.stl" scale="0.001 0.001 0.001"/>
    </geometry>
  </collision>
</link>

<link name="gripper_fr_1">
  <inertial>
    <origin rpy="0 0 0" xyz="3.494621152599908e-05 -2.8408082730690953e-05 0.01005615387645109"/>
    <mass value="0.5910681632638519"/>
    <inertia ixx="0.000326" ixy="4e-02" ixz="-1e-02" iyy="0.000326" iyz="1e-02" izz="0.000117"/>
  </inertial>
  <visual>
    <origin rpy="0 0 0" xyz="-0.333156 0.358242 -0.587313"/>
    <geometry>
      <mesh filename="package://throwing_bot_description/meshes/gripper_fr_1.stl" scale="0.001 0.001 0.001"/>
    </geometry>
    <material name="silver_default"/>
  </visual>
  <collision>
    <origin rpy="0 0 0" xyz="-0.333156 0.358242 -0.587313"/>
    <geometry>
      <mesh filename="package://throwing_bot_description/meshes/gripper_fr_1.stl" scale="0.001 0.001 0.001"/>
    </geometry>
  </collision>
</link>

<link name="gripper_ball_fr_1">
  <inertial>
    <origin rpy="0 0 0" xyz="-1.3950968541509567e-07 4.770693827760297e-07 0.035467027155031805"/>
    <mass value="0.24291657027929903"/>
    <inertia ixx="0.000159" ixy="0.0" ixz="-0.0" iyy="0.000159" iyz="-0.0" izz="0.000167"/>
  </inertial>
  <visual>
    <origin rpy="0 0 0" xyz="-0.333156 0.358242 -0.646676"/>
    <geometry>
      <mesh filename="package://throwing_bot_description/meshes/gripper_ball_fr_1.stl" scale="0.001 0.001 0.001"/>
    </geometry>
    <material name="silver_default"/>
  </visual>
  <collision>
    <origin rpy="0 0 0" xyz="-0.333156 0.358242 -0.646676"/>
    <geometry>
      <mesh filename="package://throwing_bot_description/meshes/gripper_ball_fr_1.stl" scale="0.001 0.001 0.001"/>
    </geometry>
  </collision>
</link>

<link name="gripper_bl_1">
  <inertial>
    <origin rpy="0 0 0" xyz="2.938112957079353e-05 -3.524468623544719e-05 0.010056153876451757"/>
    <mass value="0.5910681632638507"/>
    <inertia ixx="0.000326" ixy="4e-02" ixz="-1e-02" iyy="0.000326" iyz="1e-02" izz="0.000117"/>
  </inertial>
  <visual>
    <origin rpy="0 0 0" xyz="0.358242 -0.333156 -0.587313"/>
    <geometry>
      <mesh filename="package://throwing_bot_description/meshes/gripper_bl_1.stl" scale="0.001 0.001 0.001"/>
    </geometry>
    <material name="silver_default"/>
  </visual>
  <collision>
    <origin rpy="0 0 0" xyz="0.358242 -0.333156 -0.587313"/>
    <geometry>
      <mesh filename="package://throwing_bot_description/meshes/gripper_bl_1.stl" scale="0.001 0.001 0.001"/>
    </geometry>
  </collision>
</link>

<link name="gripper_ball_bl_1">
  <inertial>
    <origin rpy="0 0 0" xyz="4.959812164306854e-07 -1.589728521600442e-07 0.03546702715932515"/>
    <mass value="0.24291657038309492"/>
    <inertia ixx="0.000159" ixy="0.0" ixz="0.0" iyy="0.000159" iyz="-0.0" izz="0.000167"/>
  </inertial>
  <visual>
    <origin rpy="0 0 0" xyz="0.358242 -0.333156 -0.646676"/>
    <geometry>
      <mesh filename="package://throwing_bot_description/meshes/gripper_ball_bl_1.stl" scale="0.001 0.001 0.001"/>
    </geometry>
    <material name="silver_default"/>
  </visual>
  <collision>
    <origin rpy="0 0 0" xyz="0.358242 -0.333156 -0.646676"/>
    <geometry>
      <mesh filename="package://throwing_bot_description/meshes/gripper_ball_bl_1.stl" scale="0.001 0.001 0.001"/>
    </geometry>
  </collision>
</link>

<link name="arrow_holder_1">
  <inertial>
    <origin rpy="0 0 0" xyz="-0.0031012243650013482 -0.04280305996033454 0.012073902839088657"/>
    <mass value="0.5992891515771885"/>
    <inertia ixx="0.00072" ixy="0.000361" ixz="1.3e-02" iyy="0.000719" iyz="1.2e-02" izz="0.000914"/>
  </inertial>
  <visual>
    <origin rpy="0 0 0" xyz="-0.149004 -0.19143 -0.285039"/>
    <geometry>
      <mesh filename="package://throwing_bot_description/meshes/arrow_holder_1.stl" scale="0.001 0.001 0.001"/>
    </geometry>
    <material name="silver_default"/>
  </visual>
  <collision>
    <origin rpy="0 0 0" xyz="-0.149004 -0.19143 -0.285039"/>
    <geometry>
      <mesh filename="package://throwing_bot_description/meshes/arrow_holder_1.stl" scale="0.001 0.001 0.001"/>
    </geometry>
  </collision>
</link>

<link name="slider_rod_2">
  <inertial>
    <origin rpy="0 0 0" xyz="-0.23395526562850028 -0.40455079646653846 0.030589993822032202"/>
    <mass value="1.9072467651966203"/>
    <inertia ixx="0.007541" ixy="0.006722" ixz="1.4e-02" iyy="0.007536" iyz="3.3e-02" izz="0.013661"/>
  </inertial>
  <visual>
    <origin rpy="0 0 0" xyz="0.096358 -0.073407 -0.223416"/>
    <geometry>
      <mesh filename="package://throwing_bot_description/meshes/slider_rod_2.stl" scale="0.001 0.001 0.001"/>
    </geometry>
    <material name="silver_default"/>
  </visual>
  <collision>
    <origin rpy="0 0 0" xyz="0.096358 -0.073407 -0.223416"/>
    <geometry>
      <mesh filename="package://throwing_bot_description/meshes/slider_rod_2.stl" scale="0.001 0.001 0.001"/>
    </geometry>
  </collision>
</link>

<link name="throwing_base_1">
  <inertial>
    <origin rpy="0 0 0" xyz="0.35730528432643766 0.3572204048150748 -0.0007263816510170717"/>
    <mass value="83.15108258777522"/>
    <inertia ixx="3.06197" ixy="-2.3335" ixz="-0.039769" iyy="3.062187" iyz="-0.039717" izz="6.037185"/>
  </inertial>
  <visual>
    <origin rpy="0 0 0" xyz="0.331189 0.331189 -0.264376"/>
    <geometry>
      <mesh filename="package://throwing_bot_description/meshes/throwing_base_1.stl" scale="0.001 0.001 0.001"/>
    </geometry>
    <material name="silver_default"/>
  </visual>
  <collision>
    <origin rpy="0 0 0" xyz="0.331189 0.331189 -0.264376"/>
    <geometry>
      <mesh filename="package://throwing_bot_description/meshes/throwing_base_1.stl" scale="0.001 0.001 0.001"/>
    </geometry>
  </collision>
</link>

<link name="wheel_fl_1">
  <inertial>
    <origin rpy="0 0 0" xyz="0.031542608490837065 -0.03157966654337491 -4.62912066842569e-06"/>
    <mass value="7.448486590236144"/>
    <inertia ixx="0.021306" ixy="0.001481" ixz="-1e-06" iyy="0.021358" iyz="1e-06" izz="0.022811"/>
  </inertial>
  <visual>
    <origin rpy="0 0 0" xyz="-0.261415 0.2865 -0.0819"/>
    <geometry>
      <mesh filename="package://throwing_bot_description/meshes/wheel_fl_1.stl" scale="0.001 0.001 0.001"/>
    </geometry>
    <material name="silver_default"/>
  </visual>
  <collision>
    <origin rpy="0 0 0" xyz="-0.261415 0.2865 -0.0819"/>
    <geometry>
      <mesh filename="package://throwing_bot_description/meshes/wheel_fl_1.stl" scale="0.001 0.001 0.001"/>
    </geometry>
  </collision>
</link>

<link name="wheel_br_1">
  <inertial>
    <origin rpy="0 0 0" xyz="-0.030165434057531304 -0.030129057642393764 -4.629120670326947e-06"/>
    <mass value="7.448486590236144"/>
    <inertia ixx="0.021358" ixy="-0.001481" ixz="1e-06" iyy="0.021306" iyz="1e-06" izz="0.022811"/>
  </inertial>
  <visual>
    <origin rpy="0 0 0" xyz="0.2865 0.2865 -0.0819"/>
    <geometry>
      <mesh filename="package://throwing_bot_description/meshes/wheel_br_1.stl" scale="0.001 0.001 0.001"/>
    </geometry>
    <material name="silver_default"/>
  </visual>
  <collision>
    <origin rpy="0 0 0" xyz="0.2865 0.2865 -0.0819"/>
    <geometry>
      <mesh filename="package://throwing_bot_description/meshes/wheel_br_1.stl" scale="0.001 0.001 0.001"/>
    </geometry>
  </collision>
</link>

<link name="wheel_fr_1">
  <inertial>
    <origin rpy="0 0 0" xyz="0.028714181366090774 -0.02875123941862845 -4.629120668495079e-06"/>
    <mass value="7.448486590236144"/>
    <inertia ixx="0.021306" ixy="0.001481" ixz="-1e-06" iyy="0.021358" iyz="1e-06" izz="0.022811"/>
  </inertial>
  <visual>
    <origin rpy="0 0 0" xyz="-0.261415 0.2865 -0.0819"/>
    <geometry>
      <mesh filename="package://throwing_bot_description/meshes/wheel_fr_1.stl" scale="0.001 0.001 0.001"/>
    </geometry>
    <material name="silver_default"/>
  </visual>
  <collision>
    <origin rpy="0 0 0" xyz="-0.261415 0.2865 -0.0819"/>
    <geometry>
      <mesh filename="package://throwing_bot_description/meshes/wheel_fr_1.stl" scale="0.001 0.001 0.001"/>
    </geometry>
  </collision>
</link>

<link name="wheel_bl_1">
  <inertial>
    <origin rpy="0 0 0" xyz="-0.03012903871892364 0.03016477134360135 -4.62912066792609e-06"/>
    <mass value="7.448486590236144"/>
    <inertia ixx="0.021306" ixy="0.001481" ixz="1e-06" iyy="0.021358" iyz="-1e-06" izz="0.022811"/>
  </inertial>
  <visual>
    <origin rpy="0 0 0" xyz="0.2865 -0.261415 -0.0819"/>
    <geometry>
      <mesh filename="package://throwing_bot_description/meshes/wheel_bl_1.stl" scale="0.001 0.001 0.001"/>
    </geometry>
    <material name="silver_default"/>
  </visual>
  <collision>
    <origin rpy="0 0 0" xyz="0.2865 -0.261415 -0.0819"/>
    <geometry>
      <mesh filename="package://throwing_bot_description/meshes/wheel_bl_1.stl" scale="0.001 0.001 0.001"/>
    </geometry>
  </collision>
</link>

<link name="arrow_grasper_fr_1_1">
  <inertial>
    <origin rpy="0 0 0" xyz="0.00020995626166490922 -0.0002828105095806499 0.03807689499151412"/>
    <mass value="0.12047492253495959"/>
    <inertia ixx="6.9e-02" ixy="2e-02" ixz="-1e-02" iyy="6.9e-02" iyz="1e-02" izz="5e-02"/>
  </inertial>
  <visual>
    <origin rpy="0 0 0" xyz="0.020604 0.215944 -0.264788"/>
    <geometry>
      <mesh filename="package://throwing_bot_description/meshes/arrow_grasper_fr_1_1.stl" scale="0.001 0.001 0.001"/>
    </geometry>
    <material name="silver_default"/>
  </visual>
  <collision>
    <origin rpy="0 0 0" xyz="0.020604 0.215944 -0.264788"/>
    <geometry>
      <mesh filename="package://throwing_bot_description/meshes/arrow_grasper_fr_1_1.stl" scale="0.001 0.001 0.001"/>
    </geometry>
  </collision>
</link>

<link name="arrow_grasper_fr_2_1">
  <inertial>
    <origin rpy="0 0 0" xyz="0.00020913913033751563 -0.00028362788403006253 0.038076099395637886"/>
    <mass value="0.12047492253495959"/>
    <inertia ixx="6.9e-02" ixy="2e-02" ixz="-1e-02" iyy="6.9e-02" iyz="1e-02" izz="5e-02"/>
  </inertial>
  <visual>
    <origin rpy="0 0 0" xyz="-0.173851 0.021489 -0.265165"/>
    <geometry>
      <mesh filename="package://throwing_bot_description/meshes/arrow_grasper_fr_2_1.stl" scale="0.001 0.001 0.001"/>
    </geometry>
    <material name="silver_default"/>
  </visual>
  <collision>
    <origin rpy="0 0 0" xyz="-0.173851 0.021489 -0.265165"/>
    <geometry>
      <mesh filename="package://throwing_bot_description/meshes/arrow_grasper_fr_2_1.stl" scale="0.001 0.001 0.001"/>
    </geometry>
  </collision>
</link>

<link name="arrow_grasper_bl_1_1">
  <inertial>
    <origin rpy="0 0 0" xyz="-0.0002095273646392226 0.0001356715490000264 0.038077705325848143"/>
    <mass value="0.12047492253495959"/>
    <inertia ixx="6.9e-02" ixy="2e-02" ixz="1e-02" iyy="6.9e-02" iyz="-1e-02" izz="5e-02"/>
  </inertial>
  <visual>
    <origin rpy="0 0 0" xyz="0.215529 0.021018 -0.264788"/>
    <geometry>
      <mesh filename="package://throwing_bot_description/meshes/arrow_grasper_bl_1_1.stl" scale="0.001 0.001 0.001"/>
    </geometry>
    <material name="silver_default"/>
  </visual>
  <collision>
    <origin rpy="0 0 0" xyz="0.215529 0.021018 -0.264788"/>
    <geometry>
      <mesh filename="package://throwing_bot_description/meshes/arrow_grasper_bl_1_1.stl" scale="0.001 0.001 0.001"/>
    </geometry>
  </collision>
</link>

<link name="arrow_grasper_bl_2_1">
  <inertial>
    <origin rpy="0 0 0" xyz="-0.0002093444948764664 0.00013585441876309834 0.0380769086030453"/>
    <mass value="0.12047492253495959"/>
    <inertia ixx="6.9e-02" ixy="2e-02" ixz="1e-02" iyy="6.9e-02" iyz="-1e-02" izz="5e-02"/>
  </inertial>
  <visual>
    <origin rpy="0 0 0" xyz="0.021075 -0.173436 -0.265165"/>
    <geometry>
      <mesh filename="package://throwing_bot_description/meshes/arrow_grasper_bl_2_1.stl" scale="0.001 0.001 0.001"/>
    </geometry>
    <material name="silver_default"/>
  </visual>
  <collision>
    <origin rpy="0 0 0" xyz="0.021075 -0.173436 -0.265165"/>
    <geometry>
      <mesh filename="package://throwing_bot_description/meshes/arrow_grasper_bl_2_1.stl" scale="0.001 0.001 0.001"/>
    </geometry>
  </collision>
</link>

<joint name="dummy_link" type="fixed">
  <parent link="dummy"/>
  <child link="dummy"/>
</joint>

<joint name="roller_rotate_fr_2" type="continuous">
  <origin rpy="0 0 0" xyz="0.278375 -0.062874 0.273183"/>
  <parent link="base_link"/>
  <child link="rotating_chamber_roller_fr_2_1"/>
  <axis xyz="0.707107 0.707107 0.0"/>
</joint>

<joint name="roller_rotate_fr_1" type="continuous">
  <origin rpy="0 0 0" xyz="0.037959 -0.30329 0.273183"/>
  <parent link="base_link"/>
  <child link="rotating_chamber_roller_fr_1_1"/>
  <axis xyz="0.707107 0.707107 0.0"/>
</joint>

<joint name="roller_rotate_bl_1" type="continuous">
  <origin rpy="0 0 0" xyz="-0.306074 0.040742 0.273183"/>
  <parent link="base_link"/>
  <child link="rotating_chamber_roller_bl_1_1"/>
  <axis xyz="0.707107 0.707107 0.0"/>
</joint>

<joint name="roller_rotate_bl_2" type="continuous">
  <origin rpy="0 0 0" xyz="-0.065657 0.281159 0.273183"/>
  <parent link="base_link"/>
  <child link="rotating_chamber_roller_bl_2_1"/>
  <axis xyz="0.707107 0.707107 0.0"/>
</joint>

<joint name="gripper_arm_fr_rotate" type="continuous">
  <origin rpy="0 0 0" xyz="0.333156 -0.358242 0.242924"/>
  <parent link="base_link"/>
  <child link="gripper_arm_fr_1"/>
  <axis xyz="0.707107 0.707107 0.0"/>
</joint>

<joint name="gripper_arm_bl_rotate" type="continuous">
  <origin rpy="0 0 0" xyz="-0.358242 0.333156 0.242924"/>
  <parent link="base_link"/>
  <child link="gripper_arm_bl_1"/>
  <axis xyz="0.707107 0.707107 -0.0"/>
</joint>

<joint name="gripper_fr_rotate" type="continuous">
  <origin rpy="0 0 0" xyz="0.0 0.0 0.344389"/>
  <parent link="gripper_arm_fr_1"/>
  <child link="gripper_fr_1"/>
  <axis xyz="0.707107 0.707107 0.0"/>
</joint>

<joint name="gripper_ball_fr_rotate" type="continuous">
  <origin rpy="0 0 0" xyz="0.0 0.0 0.059363"/>
  <parent link="gripper_fr_1"/>
  <child link="gripper_ball_fr_1"/>
  <axis xyz="0.0 0.0 -1.0"/>
</joint>

<joint name="gripper_bl_rotate" type="continuous">
  <origin rpy="0 0 0" xyz="0.0 0.0 0.344389"/>
  <parent link="gripper_arm_bl_1"/>
  <child link="gripper_bl_1"/>
  <axis xyz="0.707107 0.707107 -0.0"/>
</joint>

<joint name="gripper_ball_bl_rotate" type="continuous">
  <origin rpy="0 0 0" xyz="0.0 0.0 0.059363"/>
  <parent link="gripper_bl_1"/>
  <child link="gripper_ball_bl_1"/>
  <axis xyz="0.0 0.0 1.0"/>
</joint>

<joint name="arrow_holder_slide" type="prismatic">
  <origin rpy="0 0 0" xyz="0.480193 0.522619 0.020663"/>
  <parent link="throwing_base_1"/>
  <child link="arrow_holder_1"/>
  <axis xyz="0.707106 0.707106 0.001368"/>
  <limit effort="100" lower="0.0" upper="0.0" velocity="100"/>
</joint>

<joint name="throwing_slide" type="prismatic">
  <origin rpy="0 0 0" xyz="-0.096358 0.073407 0.223416"/>
  <parent link="base_link"/>
  <child link="slider_rod_2"/>
  <axis xyz="-0.707107 -0.707107 -0.0"/>
  <limit effort="100" lower="0.0" upper="0.0" velocity="100"/>
</joint>

<joint name="throwing_rotate" type="continuous">
  <origin rpy="0 0 0" xyz="-0.234831 -0.404596 0.04096"/>
  <parent link="slider_rod_2"/>
  <child link="throwing_base_1"/>
  <axis xyz="-0.707107 0.707107 0.0"/>
</joint>

<joint name="wheel_fl_fix" type="fixed">
  <origin rpy="0 0 0" xyz="0.261415 -0.2865 0.0819"/>
  <parent link="base_link"/>
  <child link="wheel_fl_1"/>
</joint>

<joint name="wheel_br_fix" type="fixed">
  <origin rpy="0 0 0" xyz="-0.2865 -0.2865 0.0819"/>
  <parent link="base_link"/>
  <child link="wheel_br_1"/>
</joint>

<joint name="wheel_fr_fix" type="fixed">
  <origin rpy="0 0 0" xyz="0.261415 -0.2865 0.0819"/>
  <parent link="base_link"/>
  <child link="wheel_fr_1"/>
</joint>

<joint name="wheel_bl_fix" type="fixed">
  <origin rpy="0 0 0" xyz="-0.2865 0.261415 0.0819"/>
  <parent link="base_link"/>
  <child link="wheel_bl_1"/>
</joint>

<joint name="arrow_grasper_fr_1_rotate" type="continuous">
  <origin rpy="0 0 0" xyz="0.310585 0.115245 0.000412"/>
  <parent link="throwing_base_1"/>
  <child link="arrow_grasper_fr_1_1"/>
  <axis xyz="0.707106 0.707106 0.001368"/>
</joint>

<joint name="arrow_grasper_fr_2_rotate" type="continuous">
  <origin rpy="0 0 0" xyz="0.50504 0.3097 0.000789"/>
  <parent link="throwing_base_1"/>
  <child link="arrow_grasper_fr_2_1"/>
  <axis xyz="0.707106 0.707106 0.001368"/>
</joint>

<joint name="arrow_grasper_bl_1_rotate" type="continuous">
  <origin rpy="0 0 0" xyz="0.11566 0.310171 0.000412"/>
  <parent link="throwing_base_1"/>
  <child link="arrow_grasper_bl_1_1"/>
  <axis xyz="0.707106 0.707106 0.001368"/>
</joint>

<joint name="arrow_grasper_bl_2_rotate" type="continuous">
  <origin rpy="0 0 0" xyz="0.310114 0.504625 0.000789"/>
  <parent link="throwing_base_1"/>
  <child link="arrow_grasper_bl_2_1"/>
  <axis xyz="0.707106 0.707106 0.001368"/>
</joint>

</robot>
