<?xml version="1.0" ?>
<robot name="throwing_bot" xmlns:xacro="http://www.ros.org/wiki/xacro">

<xacro:include filename="$(find throwing_bot_description)/urdf/materials.xacro" />
<xacro:include filename="$(find throwing_bot_description)/urdf/throwing_bot.trans" />
<xacro:include filename="$(find throwing_bot_description)/gazebo/throwing_bot_materials.gazebo" />
<xacro:include filename="$(find throwing_bot_description)/gazebo/throwing_bot_physics.gazebo" />
<xacro:include filename="$(find throwing_bot_description)/gazebo/throwing_bot_plugins.gazebo" />
<link name="dummy">
</link>
<link name="base_link">
  <inertial>
    <origin rpy="0 0 0" xyz="-0.011790426493338684 -0.01124321266871819 0.2651352232383578"/>
    <mass value="336.84581532212275"/>
    <inertia ixx="38.959044" ixy="0.746816" ixz="0.020281" iyy="38.959828" iyz="0.012324" izz="62.892112"/>
  </inertial>
  <visual>
    <origin rpy="0 0 0" xyz="0 0 0"/>
    <geometry>
      <mesh filename="package://throwing_bot_description/meshes/base_link.stl" scale="0.001 0.001 0.001"/>
    </geometry>
    <material name="silver_default"/>
  </visual>
  <collision>
    <origin rpy="0 0 0" xyz="0 0 0"/>
    <geometry>
      <mesh filename="package://throwing_bot_description/meshes/base_link.stl" scale="0.001 0.001 0.001"/>
    </geometry>
  </collision>
</link>

<link name="rotating_chamber_roller_fr_2_1">
  <inertial>
    <origin rpy="0 0 0" xyz="9.510225135178629e-08 1.3912592169984528e-07 -0.00014705021665484264"/>
    <mass value="0.16224172662152384"/>
    <inertia ixx="4.6e-03" ixy="1.5e-03" ixz="0.0" iyy="4.6e-03" iyz="-0.0" izz="3.2e-03"/>
  </inertial>
  <visual>
    <origin rpy="0 0 0" xyz="-0.278375 0.062874 -0.313183"/>
    <geometry>
      <mesh filename="package://throwing_bot_description/meshes/rotating_chamber_roller_fr_2_1.stl" scale="0.001 0.001 0.001"/>
    </geometry>
    <material name="silver_default"/>
  </visual>
  <collision>
    <origin rpy="0 0 0" xyz="-0.278375 0.062874 -0.313183"/>
    <geometry>
      <mesh filename="package://throwing_bot_description/meshes/rotating_chamber_roller_fr_2_1.stl" scale="0.001 0.001 0.001"/>
    </geometry>
  </collision>
</link>

<link name="rotating_chamber_roller_fr_1_1">
  <inertial>
    <origin rpy="0 0 0" xyz="-2.1050117549742398e-07 -1.664775036713806e-07 -0.0001470502166586729"/>
    <mass value="0.16224172662152384"/>
    <inertia ixx="4.6e-03" ixy="1.5e-03" ixz="0.0" iyy="4.6e-03" iyz="-0.0" izz="3.2e-03"/>
  </inertial>
  <visual>
    <origin rpy="0 0 0" xyz="-0.037959 0.30329 -0.313183"/>
    <geometry>
      <mesh filename="package://throwing_bot_description/meshes/rotating_chamber_roller_fr_1_1.stl" scale="0.001 0.001 0.001"/>
    </geometry>
    <material name="silver_default"/>
  </visual>
  <collision>
    <origin rpy="0 0 0" xyz="-0.037959 0.30329 -0.313183"/>
    <geometry>
      <mesh filename="package://throwing_bot_description/meshes/rotating_chamber_roller_fr_1_1.stl" scale="0.001 0.001 0.001"/>
    </geometry>
  </collision>
</link>

<link name="rotating_chamber_roller_bl_1_1">
  <inertial>
    <origin rpy="0 0 0" xyz="2.1607366701426045e-07 4.0694766339360866e-07 -0.0001470502166551202"/>
    <mass value="0.16224172662152384"/>
    <inertia ixx="4.6e-03" ixy="1.5e-03" ixz="-0.0" iyy="4.6e-03" iyz="0.0" izz="3.2e-03"/>
  </inertial>
  <visual>
    <origin rpy="0 0 0" xyz="0.306074 -0.040742 -0.313183"/>
    <geometry>
      <mesh filename="package://throwing_bot_description/meshes/rotating_chamber_roller_bl_1_1.stl" scale="0.001 0.001 0.001"/>
    </geometry>
    <material name="silver_default"/>
  </visual>
  <collision>
    <origin rpy="0 0 0" xyz="0.306074 -0.040742 -0.313183"/>
    <geometry>
      <mesh filename="package://throwing_bot_description/meshes/rotating_chamber_roller_bl_1_1.stl" scale="0.001 0.001 0.001"/>
    </geometry>
  </collision>
</link>

<link name="rotating_chamber_roller_bl_2_1">
  <inertial>
    <origin rpy="0 0 0" xyz="-4.783229013288759e-07 -2.874489165582972e-07 -0.0001470502166511789"/>
    <mass value="0.16224172662152384"/>
    <inertia ixx="4.6e-03" ixy="1.5e-03" ixz="-0.0" iyy="4.6e-03" iyz="0.0" izz="3.2e-03"/>
  </inertial>
  <visual>
    <origin rpy="0 0 0" xyz="0.065657 -0.281159 -0.313183"/>
    <geometry>
      <mesh filename="package://throwing_bot_description/meshes/rotating_chamber_roller_bl_2_1.stl" scale="0.001 0.001 0.001"/>
    </geometry>
    <material name="silver_default"/>
  </visual>
  <collision>
    <origin rpy="0 0 0" xyz="0.065657 -0.281159 -0.313183"/>
    <geometry>
      <mesh filename="package://throwing_bot_description/meshes/rotating_chamber_roller_bl_2_1.stl" scale="0.001 0.001 0.001"/>
    </geometry>
  </collision>
</link>

<link name="gripper_arm_fr_1">
  <inertial>
    <origin rpy="0 0 0" xyz="-1.3977562096645357e-07 4.770616842675324e-07 0.1619859252578661"/>
    <mass value="19.9230589366508"/>
    <inertia ixx="0.221537" ixy="-0.00275" ixz="0.0" iyy="0.221537" iyz="0.0" izz="0.027851"/>
  </inertial>
  <visual>
    <origin rpy="0 0 0" xyz="-0.333156 0.358242 -0.282924"/>
    <geometry>
      <mesh filename="package://throwing_bot_description/meshes/gripper_arm_fr_1.stl" scale="0.001 0.001 0.001"/>
    </geometry>
    <material name="silver_default"/>
  </visual>
  <collision>
    <origin rpy="0 0 0" xyz="-0.333156 0.358242 -0.282924"/>
    <geometry>
      <mesh filename="package://throwing_bot_description/meshes/gripper_arm_fr_1.stl" scale="0.001 0.001 0.001"/>
    </geometry>
  </collision>
</link>

<link name="gripper_arm_bl_1">
  <inertial>
    <origin rpy="0 0 0" xyz="4.959851587771347e-07 -1.5869908842613967e-07 0.16198592525786654"/>
    <mass value="19.9230589366508"/>
    <inertia ixx="0.221537" ixy="-0.00275" ixz="0.0" iyy="0.221537" iyz="-0.0" izz="0.027851"/>
  </inertial>
  <visual>
    <origin rpy="0 0 0" xyz="0.358242 -0.333156 -0.282924"/>
    <geometry>
      <mesh filename="package://throwing_bot_description/meshes/gripper_arm_bl_1.stl" scale="0.001 0.001 0.001"/>
    </geometry>
    <material name="silver_default"/>
  </visual>
  <collision>
    <origin rpy="0 0 0" xyz="0.358242 -0.333156 -0.282924"/>
    <geometry>
      <mesh filename="package://throwing_bot_description/meshes/gripper_arm_bl_1.stl" scale="0.001 0.001 0.001"/>
    </geometry>
  </collision>
</link>

<link name="gripper_fr_1">
  <inertial>
    <origin rpy="0 0 0" xyz="3.4946211526054594e-05 -2.8408082730801976e-05 0.010056153876451202"/>
    <mass value="0.5910681632638519"/>
    <inertia ixx="0.000326" ixy="4e-02" ixz="-1e-02" iyy="0.000326" iyz="1e-02" izz="0.000117"/>
  </inertial>
  <visual>
    <origin rpy="0 0 0" xyz="-0.333156 0.358242 -0.627313"/>
    <geometry>
      <mesh filename="package://throwing_bot_description/meshes/gripper_fr_1.stl" scale="0.001 0.001 0.001"/>
    </geometry>
    <material name="silver_default"/>
  </visual>
  <collision>
    <origin rpy="0 0 0" xyz="-0.333156 0.358242 -0.627313"/>
    <geometry>
      <mesh filename="package://throwing_bot_description/meshes/gripper_fr_1.stl" scale="0.001 0.001 0.001"/>
    </geometry>
  </collision>
</link>

<link name="gripper_ball_fr_1">
  <inertial>
    <origin rpy="0 0 0" xyz="-1.3950968558162913e-07 4.770693825539851e-07 0.035467027155031694"/>
    <mass value="0.24291657027929903"/>
    <inertia ixx="0.000159" ixy="0.0" ixz="-0.0" iyy="0.000159" iyz="-0.0" izz="0.000167"/>
  </inertial>
  <visual>
    <origin rpy="0 0 0" xyz="-0.333156 0.358242 -0.686676"/>
    <geometry>
      <mesh filename="package://throwing_bot_description/meshes/gripper_ball_fr_1.stl" scale="0.001 0.001 0.001"/>
    </geometry>
    <material name="silver_default"/>
  </visual>
  <collision>
    <origin rpy="0 0 0" xyz="-0.333156 0.358242 -0.686676"/>
    <geometry>
      <mesh filename="package://throwing_bot_description/meshes/gripper_ball_fr_1.stl" scale="0.001 0.001 0.001"/>
    </geometry>
  </collision>
</link>

<link name="gripper_bl_1">
  <inertial>
    <origin rpy="0 0 0" xyz="2.9381129570626996e-05 -3.52446862355027e-05 0.010056153876451646"/>
    <mass value="0.5910681632638507"/>
    <inertia ixx="0.000326" ixy="4e-02" ixz="-1e-02" iyy="0.000326" iyz="1e-02" izz="0.000117"/>
  </inertial>
  <visual>
    <origin rpy="0 0 0" xyz="0.358242 -0.333156 -0.627313"/>
    <geometry>
      <mesh filename="package://throwing_bot_description/meshes/gripper_bl_1.stl" scale="0.001 0.001 0.001"/>
    </geometry>
    <material name="silver_default"/>
  </visual>
  <collision>
    <origin rpy="0 0 0" xyz="0.358242 -0.333156 -0.627313"/>
    <geometry>
      <mesh filename="package://throwing_bot_description/meshes/gripper_bl_1.stl" scale="0.001 0.001 0.001"/>
    </geometry>
  </collision>
</link>

<link name="gripper_ball_bl_1">
  <inertial>
    <origin rpy="0 0 0" xyz="4.959812163751742e-07 -1.5897285232657765e-07 0.03546702715932504"/>
    <mass value="0.24291657038309492"/>
    <inertia ixx="0.000159" ixy="0.0" ixz="0.0" iyy="0.000159" iyz="-0.0" izz="0.000167"/>
  </inertial>
  <visual>
    <origin rpy="0 0 0" xyz="0.358242 -0.333156 -0.686676"/>
    <geometry>
      <mesh filename="package://throwing_bot_description/meshes/gripper_ball_bl_1.stl" scale="0.001 0.001 0.001"/>
    </geometry>
    <material name="silver_default"/>
  </visual>
  <collision>
    <origin rpy="0 0 0" xyz="0.358242 -0.333156 -0.686676"/>
    <geometry>
      <mesh filename="package://throwing_bot_description/meshes/gripper_ball_bl_1.stl" scale="0.001 0.001 0.001"/>
    </geometry>
  </collision>
</link>

<link name="arrow_holder_1">
  <inertial>
    <origin rpy="0 0 0" xyz="-0.0031005616510704215 -0.04280339724640353 0.012073902839088546"/>
    <mass value="0.5992891515771885"/>
    <inertia ixx="0.00072" ixy="0.000361" ixz="1.3e-02" iyy="0.000719" iyz="1.2e-02" izz="0.000914"/>
  </inertial>
  <visual>
    <origin rpy="0 0 0" xyz="-0.148689 -0.191116 -0.325039"/>
    <geometry>
      <mesh filename="package://throwing_bot_description/meshes/arrow_holder_1.stl" scale="0.001 0.001 0.001"/>
    </geometry>
    <material name="silver_default"/>
  </visual>
  <collision>
    <origin rpy="0 0 0" xyz="-0.148689 -0.191116 -0.325039"/>
    <geometry>
      <mesh filename="package://throwing_bot_description/meshes/arrow_holder_1.stl" scale="0.001 0.001 0.001"/>
    </geometry>
  </collision>
</link>

<link name="slider_rod_2">
  <inertial>
    <origin rpy="0 0 0" xyz="-0.23426960291456944 -0.40486513375260774 0.030589993822032258"/>
    <mass value="1.9072467651966203"/>
    <inertia ixx="0.007541" ixy="0.006722" ixz="1.4e-02" iyy="0.007536" iyz="3.3e-02" izz="0.013661"/>
  </inertial>
  <visual>
    <origin rpy="0 0 0" xyz="0.096358 -0.073407 -0.263416"/>
    <geometry>
      <mesh filename="package://throwing_bot_description/meshes/slider_rod_2.stl" scale="0.001 0.001 0.001"/>
    </geometry>
    <material name="silver_default"/>
  </visual>
  <collision>
    <origin rpy="0 0 0" xyz="0.096358 -0.073407 -0.263416"/>
    <geometry>
      <mesh filename="package://throwing_bot_description/meshes/slider_rod_2.stl" scale="0.001 0.001 0.001"/>
    </geometry>
  </collision>
</link>

<link name="throwing_base_1">
  <inertial>
    <origin rpy="0 0 0" xyz="0.3573049470403686 0.3572200675290057 -0.0007263816510170717"/>
    <mass value="83.15108258777522"/>
    <inertia ixx="3.06197" ixy="-2.3335" ixz="-0.039769" iyy="3.062187" iyz="-0.039717" izz="6.037185"/>
  </inertial>
  <visual>
    <origin rpy="0 0 0" xyz="0.331503 0.331503 -0.304376"/>
    <geometry>
      <mesh filename="package://throwing_bot_description/meshes/throwing_base_1.stl" scale="0.001 0.001 0.001"/>
    </geometry>
    <material name="silver_default"/>
  </visual>
  <collision>
    <origin rpy="0 0 0" xyz="0.331503 0.331503 -0.304376"/>
    <geometry>
      <mesh filename="package://throwing_bot_description/meshes/throwing_base_1.stl" scale="0.001 0.001 0.001"/>
    </geometry>
  </collision>
</link>

<link name="arrow_grasper_1_2">
  <inertial>
    <origin rpy="0 0 0" xyz="0.0019775978576049708 -0.0021021447407637006 0.06444741353735595"/>
    <mass value="0.2227546747031532"/>
    <inertia ixx="0.000447" ixy="3e-02" ixz="-1.3e-02" iyy="0.000447" iyz="1.4e-02" izz="1e-02"/>
  </inertial>
  <visual>
    <origin rpy="0 0 0" xyz="0.020918 0.216258 -0.304788"/>
    <geometry>
      <mesh filename="package://throwing_bot_description/meshes/arrow_grasper_1_2.stl" scale="0.001 0.001 0.001"/>
    </geometry>
    <material name="silver_default"/>
  </visual>
  <collision>
    <origin rpy="0 0 0" xyz="0.020918 0.216258 -0.304788"/>
    <geometry>
      <mesh filename="package://throwing_bot_description/meshes/arrow_grasper_1_2.stl" scale="0.001 0.001 0.001"/>
    </geometry>
  </collision>
</link>

<link name="arrow_grasper_2_2">
  <inertial>
    <origin rpy="0 0 0" xyz="0.0019777801066416523 -0.0021019612502771283 0.06444661681575503"/>
    <mass value="0.22275467470315166"/>
    <inertia ixx="0.000447" ixy="3e-02" ixz="-1.3e-02" iyy="0.000447" iyz="1.4e-02" izz="1e-02"/>
  </inertial>
  <visual>
    <origin rpy="0 0 0" xyz="-0.173536 0.021804 -0.305165"/>
    <geometry>
      <mesh filename="package://throwing_bot_description/meshes/arrow_grasper_2_2.stl" scale="0.001 0.001 0.001"/>
    </geometry>
    <material name="silver_default"/>
  </visual>
  <collision>
    <origin rpy="0 0 0" xyz="-0.173536 0.021804 -0.305165"/>
    <geometry>
      <mesh filename="package://throwing_bot_description/meshes/arrow_grasper_2_2.stl" scale="0.001 0.001 0.001"/>
    </geometry>
  </collision>
</link>

<link name="arrow_grasper_4_2">
  <inertial>
    <origin rpy="0 0 0" xyz="-0.0019776606637760333 0.001852464717660901 0.06445426800929166"/>
    <mass value="0.2227546747031517"/>
    <inertia ixx="0.000447" ixy="3e-02" ixz="-1.3e-02" iyy="0.000447" iyz="1.4e-02" izz="1e-02"/>
  </inertial>
  <visual>
    <origin rpy="0 0 0" xyz="0.021389 -0.173122 -0.305165"/>
    <geometry>
      <mesh filename="package://throwing_bot_description/meshes/arrow_grasper_4_2.stl" scale="0.001 0.001 0.001"/>
    </geometry>
    <material name="silver_default"/>
  </visual>
  <collision>
    <origin rpy="0 0 0" xyz="0.021389 -0.173122 -0.305165"/>
    <geometry>
      <mesh filename="package://throwing_bot_description/meshes/arrow_grasper_4_2.stl" scale="0.001 0.001 0.001"/>
    </geometry>
  </collision>
</link>

<link name="arrow_grasper_3_2">
  <inertial>
    <origin rpy="0 0 0" xyz="-0.0019778441542642744 0.0018522824686214995 0.06445506473329449"/>
    <mass value="0.2227546747031532"/>
    <inertia ixx="0.000447" ixy="3e-02" ixz="-1.3e-02" iyy="0.000447" iyz="1.4e-02" izz="1e-02"/>
  </inertial>
  <visual>
    <origin rpy="0 0 0" xyz="0.215843 0.021332 -0.304788"/>
    <geometry>
      <mesh filename="package://throwing_bot_description/meshes/arrow_grasper_3_2.stl" scale="0.001 0.001 0.001"/>
    </geometry>
    <material name="silver_default"/>
  </visual>
  <collision>
    <origin rpy="0 0 0" xyz="0.215843 0.021332 -0.304788"/>
    <geometry>
      <mesh filename="package://throwing_bot_description/meshes/arrow_grasper_3_2.stl" scale="0.001 0.001 0.001"/>
    </geometry>
  </collision>
</link>

<link name="wheel_fl_1">
  <inertial>
    <origin rpy="0 0 0" xyz="0.028714288147278832 0.028750664562414208 4.62912067131227e-06"/>
    <mass value="7.448486590236144"/>
    <inertia ixx="0.021306" ixy="-0.001481" ixz="1e-06" iyy="0.021358" iyz="1e-06" izz="0.022811"/>
  </inertial>
  <visual>
    <origin rpy="0 0 0" xyz="-0.262122 -0.262122 -0.0819"/>
    <geometry>
      <mesh filename="package://throwing_bot_description/meshes/wheel_fl_1.stl" scale="0.001 0.001 0.001"/>
    </geometry>
    <material name="silver_default"/>
  </visual>
  <collision>
    <origin rpy="0 0 0" xyz="-0.262122 -0.262122 -0.0819"/>
    <geometry>
      <mesh filename="package://throwing_bot_description/meshes/wheel_fl_1.stl" scale="0.001 0.001 0.001"/>
    </geometry>
  </collision>
</link>

<link name="wheel_br_1">
  <inertial>
    <origin rpy="0 0 0" xyz="-0.03016543405753125 -0.030129057642393597 -4.629120670299192e-06"/>
    <mass value="7.448486590236144"/>
    <inertia ixx="0.021358" ixy="-0.001481" ixz="1e-06" iyy="0.021306" iyz="1e-06" izz="0.022811"/>
  </inertial>
  <visual>
    <origin rpy="0 0 0" xyz="0.2865 0.2865 -0.0819"/>
    <geometry>
      <mesh filename="package://throwing_bot_description/meshes/wheel_br_1.stl" scale="0.001 0.001 0.001"/>
    </geometry>
    <material name="silver_default"/>
  </visual>
  <collision>
    <origin rpy="0 0 0" xyz="0.2865 0.2865 -0.0819"/>
    <geometry>
      <mesh filename="package://throwing_bot_description/meshes/wheel_br_1.stl" scale="0.001 0.001 0.001"/>
    </geometry>
  </collision>
</link>

<link name="wheel_fr_1">
  <inertial>
    <origin rpy="0 0 0" xyz="0.02871428814727739 -0.028751346199814953 -4.62912066842569e-06"/>
    <mass value="7.448486590236144"/>
    <inertia ixx="0.021306" ixy="0.001481" ixz="-1e-06" iyy="0.021358" iyz="1e-06" izz="0.022811"/>
  </inertial>
  <visual>
    <origin rpy="0 0 0" xyz="-0.262122 0.287207 -0.0819"/>
    <geometry>
      <mesh filename="package://throwing_bot_description/meshes/wheel_fr_1.stl" scale="0.001 0.001 0.001"/>
    </geometry>
    <material name="silver_default"/>
  </visual>
  <collision>
    <origin rpy="0 0 0" xyz="-0.262122 0.287207 -0.0819"/>
    <geometry>
      <mesh filename="package://throwing_bot_description/meshes/wheel_fr_1.stl" scale="0.001 0.001 0.001"/>
    </geometry>
  </collision>
</link>

<link name="wheel_bl_1">
  <inertial>
    <origin rpy="0 0 0" xyz="-0.030128931937736025 0.03016566456241443 -4.629120669702447e-06"/>
    <mass value="7.448486590236144"/>
    <inertia ixx="0.021306" ixy="0.001481" ixz="1e-06" iyy="0.021358" iyz="-1e-06" izz="0.022811"/>
  </inertial>
  <visual>
    <origin rpy="0 0 0" xyz="0.285793 -0.260707 -0.0819"/>
    <geometry>
      <mesh filename="package://throwing_bot_description/meshes/wheel_bl_1.stl" scale="0.001 0.001 0.001"/>
    </geometry>
    <material name="silver_default"/>
  </visual>
  <collision>
    <origin rpy="0 0 0" xyz="0.285793 -0.260707 -0.0819"/>
    <geometry>
      <mesh filename="package://throwing_bot_description/meshes/wheel_bl_1.stl" scale="0.001 0.001 0.001"/>
    </geometry>
  </collision>
</link>

<joint name="dummy_joint" type="fixed">
  <parent link="dummy"/>
  <child link="base_link"/>
</joint>

<joint name="roller_rotate_fr_2" type="continuous">
  <origin rpy="0 0 0" xyz="0.278375 -0.062874 0.313183"/>
  <parent link="base_link"/>
  <child link="rotating_chamber_roller_fr_2_1"/>
  <axis xyz="0.707107 0.707107 0.0"/>
</joint>

<joint name="roller_rotate_fr_1" type="continuous">
  <origin rpy="0 0 0" xyz="0.037959 -0.30329 0.313183"/>
  <parent link="base_link"/>
  <child link="rotating_chamber_roller_fr_1_1"/>
  <axis xyz="0.707107 0.707107 0.0"/>
</joint>

<joint name="roller_rotate_bl_1" type="continuous">
  <origin rpy="0 0 0" xyz="-0.306074 0.040742 0.313183"/>
  <parent link="base_link"/>
  <child link="rotating_chamber_roller_bl_1_1"/>
  <axis xyz="-0.707107 -0.707107 -0.0"/>
</joint>

<joint name="roller_rotate_bl_2" type="continuous">
  <origin rpy="0 0 0" xyz="-0.065657 0.281159 0.313183"/>
  <parent link="base_link"/>
  <child link="rotating_chamber_roller_bl_2_1"/>
  <axis xyz="-0.707107 -0.707107 -0.0"/>
</joint>

<joint name="gripper_arm_fr_rotate" type="continuous">
  <origin rpy="0 0 0" xyz="0.333156 -0.358242 0.282924"/>
  <parent link="base_link"/>
  <child link="gripper_arm_fr_1"/>
  <axis xyz="0.707107 0.707107 0.0"/>
</joint>

<joint name="gripper_arm_bl_rotate" type="continuous">
  <origin rpy="0 0 0" xyz="-0.358242 0.333156 0.282924"/>
  <parent link="base_link"/>
  <child link="gripper_arm_bl_1"/>
  <axis xyz="-0.707107 -0.707107 0.0"/>
</joint>

<joint name="gripper_fr_rotate" type="continuous">
  <origin rpy="0 0 0" xyz="0.0 0.0 0.344389"/>
  <parent link="gripper_arm_fr_1"/>
  <child link="gripper_fr_1"/>
  <axis xyz="0.707107 0.707107 0.0"/>
</joint>

<joint name="gripper_ball_fr_rotate" type="continuous">
  <origin rpy="0 0 0" xyz="0.0 0.0 0.059363"/>
  <parent link="gripper_fr_1"/>
  <child link="gripper_ball_fr_1"/>
  <axis xyz="0.0 0.0 -1.0"/>
</joint>

<joint name="gripper_bl_rotate" type="continuous">
  <origin rpy="0 0 0" xyz="0.0 0.0 0.344389"/>
  <parent link="gripper_arm_bl_1"/>
  <child link="gripper_bl_1"/>
  <axis xyz="0.707107 0.707107 -0.0"/>
</joint>

<joint name="gripper_ball_bl_rotate" type="continuous">
  <origin rpy="0 0 0" xyz="0.0 0.0 0.059363"/>
  <parent link="gripper_bl_1"/>
  <child link="gripper_ball_bl_1"/>
  <axis xyz="0.0 0.0 1.0"/>
</joint>

<joint name="arrow_holder_slide" type="prismatic">
  <origin rpy="0 0 0" xyz="0.480192 0.522619 0.020663"/>
  <parent link="throwing_base_1"/>
  <child link="arrow_holder_1"/>
  <axis xyz="0.707106 0.707106 0.001368"/>
  <limit effort="100" lower="0.0" upper="0.0" velocity="100"/>
</joint>

<joint name="throwing_slide" type="prismatic">
  <origin rpy="0 0 0" xyz="-0.096358 0.073407 0.263416"/>
  <parent link="base_link"/>
  <child link="slider_rod_2"/>
  <axis xyz="0.707107 0.707107 0.0"/>
  <limit effort="100" lower="0.0" upper="0.0" velocity="100"/>
</joint>

<joint name="throwing_rotate" type="continuous">
  <origin rpy="0 0 0" xyz="-0.235145 -0.40491 0.04096"/>
  <parent link="slider_rod_2"/>
  <child link="throwing_base_1"/>
  <axis xyz="-0.707107 0.707107 0.0"/>
</joint>

<joint name="arrow_grasper_1_joint" type="continuous">
  <origin rpy="0 0 0" xyz="0.310585 0.115245 0.000412"/>
  <parent link="throwing_base_1"/>
  <child link="arrow_grasper_1_2"/>
  <axis xyz="0.707106 0.707106 0.001368"/>
</joint>

<joint name="arrow_graper_2_joint" type="continuous">
  <origin rpy="0 0 0" xyz="0.505039 0.309699 0.000789"/>
  <parent link="throwing_base_1"/>
  <child link="arrow_grasper_2_2"/>
  <axis xyz="0.707106 0.707106 0.001368"/>
</joint>

<joint name="arrow_grasper_4_joint" type="continuous">
  <origin rpy="0 0 0" xyz="0.310114 0.504625 0.000789"/>
  <parent link="throwing_base_1"/>
  <child link="arrow_grasper_4_2"/>
  <axis xyz="-0.707106 -0.707106 -0.001368"/>
</joint>

<joint name="arrow_grasper_3_joint" type="continuous">
  <origin rpy="0 0 0" xyz="0.11566 0.310171 0.000412"/>
  <parent link="throwing_base_1"/>
  <child link="arrow_grasper_3_2"/>
  <axis xyz="-0.707106 -0.707106 -0.001368"/>
</joint>

<joint name="wheel_fl_fix" type="fixed">
  <origin rpy="0 0 0" xyz="0.262122 0.262122 0.0819"/>
  <parent link="base_link"/>
  <child link="wheel_fl_1"/>
</joint>

<joint name="wheel_br_fix" type="fixed">
  <origin rpy="0 0 0" xyz="-0.2865 -0.2865 0.0819"/>
  <parent link="base_link"/>
  <child link="wheel_br_1"/>
</joint>

<joint name="wheel_fr_fix" type="fixed">
  <origin rpy="0 0 0" xyz="0.262122 -0.287207 0.0819"/>
  <parent link="base_link"/>
  <child link="wheel_fr_1"/>
</joint>

<joint name="wheel_bl_fix" type="fixed">
  <origin rpy="0 0 0" xyz="-0.285793 0.260707 0.0819"/>
  <parent link="base_link"/>
  <child link="wheel_bl_1"/>
</joint>

</robot>
