<?xml version="1.0" encoding="utf-8"?>
<!-- This URDF was automatically created by SolidWorks to URDF Exporter! Originally created by Stephen Brawner (brawner@gmail.com) 
     Commit Version: 1.6.0-1-g15f4949  Build Version: 1.6.7594.29634
     For more information, please see http://wiki.ros.org/sw_urdf_exporter -->
<robot
  name="Final_assembly_robocon1">
  <link
    name="base_link">
    <inertial>
      <origin
        xyz="-1.37853384098331E-07 0.00911018032229258 -0.0138175795946178"
        rpy="0 0 0" />
      <mass
        value="3.33742395913258" />
      <inertia
        ixx="0.250426120078326"
        ixy="-3.00125460809131E-08"
        ixz="4.78803539427229E-09"
        iyy="0.51613258114542"
        iyz="-5.01539743876125E-05"
        izz="0.266376294317245" />
    </inertial>
    <visual>
      <origin
        xyz="0 0 0"
        rpy="0 0 0" />
      <geometry>
        <mesh
          filename="package://Final_assembly_robocon1/meshes/base_link.STL" />
      </geometry>
      <material
        name="">
        <color
          rgba="0.792156862745098 0.819607843137255 0.933333333333333 1" />
      </material>
    </visual>
    <collision>
      <origin
        xyz="0 0 0"
        rpy="0 0 0" />
      <geometry>
        <mesh
          filename="package://Final_assembly_robocon1/meshes/base_link.STL" />
      </geometry>
    </collision>
  </link>
  <link
    name="front_left">
    <inertial>
      <origin
        xyz="-5.5511E-17 1.0408E-16 0.11113"
        rpy="0 0 0" />
      <mass
        value="0.80093" />
      <inertia
        ixx="0.0012851"
        ixy="1.3067E-18"
        ixz="-5.9631E-19"
        iyy="0.0012851"
        iyz="5.2252E-19"
        izz="0.0025006" />
    </inertial>
    <visual>
      <origin
        xyz="0 0 0"
        rpy="0 0 0" />
      <geometry>
        <mesh
          filename="package://Final_assembly_robocon1/meshes/front_left.STL" />
      </geometry>
      <material
        name="">
        <color
          rgba="0.79216 0.81961 0.93333 1" />
      </material>
    </visual>
    <collision>
      <origin
        xyz="0 0 0"
        rpy="0 0 0" />
      <geometry>
        <mesh
          filename="package://Final_assembly_robocon1/meshes/front_left.STL" />
      </geometry>
    </collision>
  </link>
  <joint
    name="front_left_joint"
    type="continuous">
    <origin
      xyz="0.29871 -0.29871 0.0442"
      rpy="1.5708 -0.008552 0.7854" />
    <parent
      link="base_link" />
    <child
      link="front_left" />
    <axis
      xyz="0 0 1" />
    <limit
      effort="10"
      velocity="10" />
    <dynamics
      damping="1000"
      friction="1000" />
  </joint>
  <link
    name="front_right">
    <inertial>
      <origin
        xyz="-2.7756E-17 8.3267E-17 0.00097337"
        rpy="0 0 0" />
      <mass
        value="0.80093" />
      <inertia
        ixx="0.0012851"
        ixy="9.6743E-19"
        ixz="-1.0842E-19"
        iyy="0.0012851"
        iyz="-3.8401E-19"
        izz="0.0025006" />
    </inertial>
    <visual>
      <origin
        xyz="0 0 0"
        rpy="0 0 0" />
      <geometry>
        <mesh
          filename="package://Final_assembly_robocon1/meshes/front_right.STL" />
      </geometry>
      <material
        name="">
        <color
          rgba="0.79216 0.81961 0.93333 1" />
      </material>
    </visual>
    <collision>
      <origin
        xyz="0 0 0"
        rpy="0 0 0" />
      <geometry>
        <mesh
          filename="package://Final_assembly_robocon1/meshes/front_right.STL" />
      </geometry>
    </collision>
  </link>
  <joint
    name="front_right_joint"
    type="continuous">
    <origin
      xyz="-0.29871 -0.29871 0.0442"
      rpy="0.016141 0.036849 -0.78477" />
    <parent
      link="base_link" />
    <child
      link="front_right" />
    <axis
      xyz="-0.00062478 -0.99987 0.016117" />
    <limit
      effort="10"
      velocity="10" />
    <dynamics
      damping="1000"
      friction="1000" />
  </joint>
  <link
    name="back_left">
    <inertial>
      <origin
        xyz="2.7756E-17 9.7145E-17 0.00097337"
        rpy="0 0 0" />
      <mass
        value="0.80093" />
      <inertia
        ixx="0.0012851"
        ixy="1.2468E-18"
        ixz="2.7105E-19"
        iyy="0.0012851"
        iyz="-2.6834E-18"
        izz="0.0025006" />
    </inertial>
    <visual>
      <origin
        xyz="0 0 0"
        rpy="0 0 0" />
      <geometry>
        <mesh
          filename="package://Final_assembly_robocon1/meshes/back_left.STL" />
      </geometry>
      <material
        name="">
        <color
          rgba="0.79216 0.81961 0.93333 1" />
      </material>
    </visual>
    <collision>
      <origin
        xyz="0 0 0"
        rpy="0 0 0" />
      <geometry>
        <mesh
          filename="package://Final_assembly_robocon1/meshes/back_left.STL" />
      </geometry>
    </collision>
  </link>
  <joint
    name="back_left_joint"
    type="continuous">
    <origin
      xyz="0.29871 0.29871 0.0442"
      rpy="0.016141 0.036849 -0.78477" />
    <parent
      link="base_link" />
    <child
      link="back_left" />
    <axis
      xyz="0.00062478 0.99987 -0.016117" />
    <limit
      effort="10"
      velocity="10" />
    <dynamics
      damping="1000"
      friction="1000" />
  </joint>
  <link
    name="back_right">
    <inertial>
      <origin
        xyz="2.7756E-17 9.7145E-17 -1.00097337"
        rpy="0 0 0" />
      <mass
        value="0.8" />
      <inertia
        ixx="0.0013851"
        ixy="9.6743E-19"
        ixz="-1.0842E-19"
        iyy="0.0012851"
        iyz="-3.8401E-19"
        izz="0.0025006" />
    </inertial>
    <visual>
      <origin
        xyz="0 0 0"
        rpy="0 0 0" />
      <geometry>
        <mesh
          filename="package://Final_assembly_robocon1/meshes/back_right.STL" />
      </geometry>
      <material
        name="">
        <color
          rgba="1 1 1 1" />
      </material>
    </visual>
    <collision>
      <origin
        xyz="0 0 0"
        rpy="0 0 0" />
      <geometry>
        <mesh
          filename="package://Final_assembly_robocon1/meshes/back_right.STL" />
      </geometry>
    </collision>
  </link>
  <joint
    name="back_right_joint"
    type="continuous">
    <origin
      xyz="-0.29871 0.29871 0.0442"
      rpy="1.5708 -0.008552 0.7854" />
    <parent
      link="base_link" />
    <child
      link="back_right" />
    <axis
      xyz="0 0 -1" />
    <limit
      effort="10"
      velocity="10" />
    <dynamics
      damping="1000"
      friction="1000" />
  </joint>
</robot>